<?xml version="1.0" encoding="UTF-8"?>
<testng-results skipped="0" failed="1" total="1" passed="0">
  <reporter-output>
  </reporter-output>
  <suite name="RegressionSutie" duration-ms="3496" started-at="2017-08-21T13:38:48Z" finished-at="2017-08-21T13:38:52Z">
    <groups>
    </groups>
    <test name="CialfoNewversion" duration-ms="3496" started-at="2017-08-21T13:38:48Z" finished-at="2017-08-21T13:38:52Z">
      <class name="BasePackage.BaseClass">
        <test-method status="PASS" signature="launchAUTApplication()[pri:0, instance:BasePackage.BaseClass@77cd7a0]" name="launchAUTApplication" is-config="true" duration-ms="8491" started-at="2017-08-21T19:08:40Z" finished-at="2017-08-21T19:08:48Z">
          <reporter-output>
          </reporter-output>
        </test-method> <!-- launchAUTApplication -->
        <test-method status="PASS" signature="cleanUp()[pri:0, instance:BasePackage.BaseClass@77cd7a0]" name="cleanUp" is-config="true" duration-ms="92" started-at="2017-08-21T19:08:52Z" finished-at="2017-08-21T19:08:52Z">
          <reporter-output>
          </reporter-output>
        </test-method> <!-- cleanUp -->
      </class> <!-- BasePackage.BaseClass -->
      <class name="TestCialfoNew.MyTest">
        <test-method status="FAIL" signature="hdhd()[pri:0, instance:TestCialfoNew.MyTest@204f30ec]" name="hdhd" duration-ms="3463" started-at="2017-08-21T19:08:48Z" finished-at="2017-08-21T19:08:52Z">
          <exception class="java.lang.AssertionError">
            <message>
              <![CDATA[expected [true] but found [false]]]>
            </message>
            <full-stacktrace>
              <![CDATA[java.lang.AssertionError: expected [true] but found [false]
	at org.testng.Assert.fail(Assert.java:94)
	at org.testng.Assert.failNotEquals(Assert.java:513)
	at org.testng.Assert.assertEqualsImpl(Assert.java:135)
	at org.testng.Assert.assertEquals(Assert.java:116)
	at org.testng.Assert.assertEquals(Assert.java:305)
	at org.testng.Assert.assertEquals(Assert.java:315)
	at TestCialfoNew.MyTest.hdhd(MyTest.java:49)
	at sun.reflect.NativeMethodAccessorImpl.invoke0(Native Method)
	at sun.reflect.NativeMethodAccessorImpl.invoke(Unknown Source)
	at sun.reflect.DelegatingMethodAccessorImpl.invoke(Unknown Source)
	at java.lang.reflect.Method.invoke(Unknown Source)
	at org.testng.internal.MethodInvocationHelper.invokeMethod(MethodInvocationHelper.java:100)
	at org.testng.internal.Invoker.invokeMethod(Invoker.java:646)
	at org.testng.internal.Invoker.invokeTestMethod(Invoker.java:811)
	at org.testng.internal.Invoker.invokeTestMethods(Invoker.java:1129)
	at org.testng.internal.TestMethodWorker.invokeTestMethods(TestMethodWorker.java:129)
	at org.testng.internal.TestMethodWorker.run(TestMethodWorker.java:112)
	at org.testng.TestRunner.privateRun(TestRunner.java:746)
	at org.testng.TestRunner.run(TestRunner.java:600)
	at org.testng.SuiteRunner.runTest(SuiteRunner.java:366)
	at org.testng.SuiteRunner.runSequentially(SuiteRunner.java:361)
	at org.testng.SuiteRunner.privateRun(SuiteRunner.java:319)
	at org.testng.SuiteRunner.run(SuiteRunner.java:268)
	at org.testng.SuiteRunnerWorker.runSuite(SuiteRunnerWorker.java:52)
	at org.testng.SuiteRunnerWorker.run(SuiteRunnerWorker.java:86)
	at org.testng.TestNG.runSuitesSequentially(TestNG.java:1264)
	at org.testng.TestNG.runSuitesLocally(TestNG.java:1189)
	at org.testng.TestNG.runSuites(TestNG.java:1104)
	at org.testng.TestNG.run(TestNG.java:1076)
	at org.testng.remote.AbstractRemoteTestNG.run(AbstractRemoteTestNG.java:126)
	at org.testng.remote.RemoteTestNG.initAndRun(RemoteTestNG.java:152)
	at org.testng.remote.RemoteTestNG.main(RemoteTestNG.java:57)
]]>
            </full-stacktrace>
          </exception> <!-- java.lang.AssertionError -->
          <reporter-output>
          </reporter-output>
        </test-method> <!-- hdhd -->
      </class> <!-- TestCialfoNew.MyTest -->
    </test> <!-- CialfoNewversion -->
  </suite> <!-- RegressionSutie -->
</testng-results>
